[2021-09-26T16:08:52+0800] [WARNING] [root] [pid:52777] [/Users/xiezhaorong/Desktop/my_py/djmyframework/djmyframework/framework/middleware.py:82] Traceback (most recent call last):
  File "/Users/xiezhaorong/Desktop/my_py/djmyframework/.venv/lib/python3.7/site-packages/django/core/handlers/base.py", line 113, in _get_response
    response = wrapped_callback(request, *callback_args, **callback_kwargs)
  File "/Users/xiezhaorong/Desktop/my_py/djmyframework/djmyframework/apps/analysis/views/query.py", line 164, in query_view
    return query_export_do(request, query_compiler)
  File "/Users/xiezhaorong/Desktop/my_py/djmyframework/djmyframework/apps/analysis/views/query.py", line 273, in query_export_do
    export_file_name, list_data, fields, export_indexs, page_num, page_size, total_record)
NameError: name 'page_size' is not defined

[2021-09-26T16:08:52+0800] [ERROR] [django.request] [pid:52777] [/Users/xiezhaorong/Desktop/my_py/djmyframework/.venv/lib/python3.7/site-packages/django/utils/log.py:228] Internal Server Error: /analysis/query/view
[2021-09-26T16:09:04+0800] [WARNING] [root] [pid:52777] [/Users/xiezhaorong/Desktop/my_py/djmyframework/djmyframework/framework/middleware.py:82] Traceback (most recent call last):
  File "/Users/xiezhaorong/Desktop/my_py/djmyframework/.venv/lib/python3.7/site-packages/django/core/handlers/base.py", line 113, in _get_response
    response = wrapped_callback(request, *callback_args, **callback_kwargs)
  File "/Users/xiezhaorong/Desktop/my_py/djmyframework/djmyframework/apps/analysis/views/query.py", line 164, in query_view
    return query_export_do(request, query_compiler)
  File "/Users/xiezhaorong/Desktop/my_py/djmyframework/djmyframework/apps/analysis/views/query.py", line 273, in query_export_do
    export_file_name, list_data, fields, export_indexs, page_num, page_size, total_record)
NameError: name 'page_size' is not defined

[2021-09-26T16:09:04+0800] [ERROR] [django.request] [pid:52777] [/Users/xiezhaorong/Desktop/my_py/djmyframework/.venv/lib/python3.7/site-packages/django/utils/log.py:228] Internal Server Error: /analysis/query/view
[2021-09-26T16:09:07+0800] [WARNING] [root] [pid:52777] [/Users/xiezhaorong/Desktop/my_py/djmyframework/djmyframework/framework/middleware.py:82] Traceback (most recent call last):
  File "/Users/xiezhaorong/Desktop/my_py/djmyframework/.venv/lib/python3.7/site-packages/django/core/handlers/base.py", line 113, in _get_response
    response = wrapped_callback(request, *callback_args, **callback_kwargs)
  File "/Users/xiezhaorong/Desktop/my_py/djmyframework/djmyframework/apps/analysis/views/query.py", line 164, in query_view
    return query_export_do(request, query_compiler)
  File "/Users/xiezhaorong/Desktop/my_py/djmyframework/djmyframework/apps/analysis/views/query.py", line 273, in query_export_do
    export_file_name, list_data, fields, export_indexs, page_num, page_size, total_record)
NameError: name 'page_size' is not defined

[2021-09-26T16:09:07+0800] [ERROR] [django.request] [pid:52777] [/Users/xiezhaorong/Desktop/my_py/djmyframework/.venv/lib/python3.7/site-packages/django/utils/log.py:228] Internal Server Error: /analysis/query/view
[2021-09-26T16:09:08+0800] [WARNING] [root] [pid:52777] [/Users/xiezhaorong/Desktop/my_py/djmyframework/djmyframework/framework/middleware.py:82] Traceback (most recent call last):
  File "/Users/xiezhaorong/Desktop/my_py/djmyframework/.venv/lib/python3.7/site-packages/django/core/handlers/base.py", line 113, in _get_response
    response = wrapped_callback(request, *callback_args, **callback_kwargs)
  File "/Users/xiezhaorong/Desktop/my_py/djmyframework/djmyframework/apps/analysis/views/query.py", line 164, in query_view
    return query_export_do(request, query_compiler)
  File "/Users/xiezhaorong/Desktop/my_py/djmyframework/djmyframework/apps/analysis/views/query.py", line 273, in query_export_do
    export_file_name, list_data, fields, export_indexs, page_num, page_size, total_record)
NameError: name 'page_size' is not defined

[2021-09-26T16:09:08+0800] [ERROR] [django.request] [pid:52777] [/Users/xiezhaorong/Desktop/my_py/djmyframework/.venv/lib/python3.7/site-packages/django/utils/log.py:228] Internal Server Error: /analysis/query/view
[2021-09-26T16:09:14+0800] [WARNING] [root] [pid:52777] [/Users/xiezhaorong/Desktop/my_py/djmyframework/djmyframework/framework/middleware.py:82] Traceback (most recent call last):
  File "/Users/xiezhaorong/Desktop/my_py/djmyframework/.venv/lib/python3.7/site-packages/django/core/handlers/base.py", line 113, in _get_response
    response = wrapped_callback(request, *callback_args, **callback_kwargs)
  File "/Users/xiezhaorong/Desktop/my_py/djmyframework/djmyframework/apps/analysis/views/query.py", line 164, in query_view
    return query_export_do(request, query_compiler)
  File "/Users/xiezhaorong/Desktop/my_py/djmyframework/djmyframework/apps/analysis/views/query.py", line 273, in query_export_do
    export_file_name, list_data, fields, export_indexs, page_num, page_size, total_record)
NameError: name 'page_size' is not defined

[2021-09-26T16:09:14+0800] [ERROR] [django.request] [pid:52777] [/Users/xiezhaorong/Desktop/my_py/djmyframework/.venv/lib/python3.7/site-packages/django/utils/log.py:228] Internal Server Error: /analysis/query/view
[2021-09-26T16:09:15+0800] [WARNING] [root] [pid:52777] [/Users/xiezhaorong/Desktop/my_py/djmyframework/djmyframework/framework/middleware.py:82] Traceback (most recent call last):
  File "/Users/xiezhaorong/Desktop/my_py/djmyframework/.venv/lib/python3.7/site-packages/django/core/handlers/base.py", line 113, in _get_response
    response = wrapped_callback(request, *callback_args, **callback_kwargs)
  File "/Users/xiezhaorong/Desktop/my_py/djmyframework/djmyframework/apps/analysis/views/query.py", line 164, in query_view
    return query_export_do(request, query_compiler)
  File "/Users/xiezhaorong/Desktop/my_py/djmyframework/djmyframework/apps/analysis/views/query.py", line 273, in query_export_do
    export_file_name, list_data, fields, export_indexs, page_num, page_size, total_record)
NameError: name 'page_size' is not defined

[2021-09-26T16:09:15+0800] [ERROR] [django.request] [pid:52777] [/Users/xiezhaorong/Desktop/my_py/djmyframework/.venv/lib/python3.7/site-packages/django/utils/log.py:228] Internal Server Error: /analysis/query/view
[2021-09-26T16:09:16+0800] [WARNING] [root] [pid:52777] [/Users/xiezhaorong/Desktop/my_py/djmyframework/djmyframework/framework/middleware.py:82] Traceback (most recent call last):
  File "/Users/xiezhaorong/Desktop/my_py/djmyframework/.venv/lib/python3.7/site-packages/django/core/handlers/base.py", line 113, in _get_response
    response = wrapped_callback(request, *callback_args, **callback_kwargs)
  File "/Users/xiezhaorong/Desktop/my_py/djmyframework/djmyframework/apps/analysis/views/query.py", line 164, in query_view
    return query_export_do(request, query_compiler)
  File "/Users/xiezhaorong/Desktop/my_py/djmyframework/djmyframework/apps/analysis/views/query.py", line 273, in query_export_do
    export_file_name, list_data, fields, export_indexs, page_num, page_size, total_record)
NameError: name 'page_size' is not defined

[2021-09-26T16:09:16+0800] [ERROR] [django.request] [pid:52777] [/Users/xiezhaorong/Desktop/my_py/djmyframework/.venv/lib/python3.7/site-packages/django/utils/log.py:228] Internal Server Error: /analysis/query/view
[2021-09-26T16:09:16+0800] [WARNING] [root] [pid:52777] [/Users/xiezhaorong/Desktop/my_py/djmyframework/djmyframework/framework/middleware.py:82] Traceback (most recent call last):
  File "/Users/xiezhaorong/Desktop/my_py/djmyframework/.venv/lib/python3.7/site-packages/django/core/handlers/base.py", line 113, in _get_response
    response = wrapped_callback(request, *callback_args, **callback_kwargs)
  File "/Users/xiezhaorong/Desktop/my_py/djmyframework/djmyframework/apps/analysis/views/query.py", line 164, in query_view
    return query_export_do(request, query_compiler)
  File "/Users/xiezhaorong/Desktop/my_py/djmyframework/djmyframework/apps/analysis/views/query.py", line 273, in query_export_do
    export_file_name, list_data, fields, export_indexs, page_num, page_size, total_record)
NameError: name 'page_size' is not defined

[2021-09-26T16:09:16+0800] [ERROR] [django.request] [pid:52777] [/Users/xiezhaorong/Desktop/my_py/djmyframework/.venv/lib/python3.7/site-packages/django/utils/log.py:228] Internal Server Error: /analysis/query/view
