[2021-10-02T15:21:00+0800] [WARNING] [root] [pid:56644] [/Users/xiezhaorong/Desktop/my_py/djmyframework/djmyframework/framework/middleware.py:82] Traceback (most recent call last):
  File "/Users/xiezhaorong/Desktop/my_py/djmyframework/.venv/lib/python3.7/site-packages/django/db/backends/utils.py", line 86, in _execute
    return self.cursor.execute(sql, params)
  File "/Users/xiezhaorong/Desktop/my_py/djmyframework/.venv/lib/python3.7/site-packages/django/db/backends/sqlite3/base.py", line 396, in execute
    return Database.Cursor.execute(self, query, params)
sqlite3.IntegrityError: UNIQUE constraint failed: analysis_query.name

The above exception was the direct cause of the following exception:

Traceback (most recent call last):
  File "/Users/xiezhaorong/Desktop/my_py/djmyframework/.venv/lib/python3.7/site-packages/django/core/handlers/base.py", line 113, in _get_response
    response = wrapped_callback(request, *callback_args, **callback_kwargs)
  File "/Users/xiezhaorong/Desktop/my_py/djmyframework/djmyframework/apps/sync_model/views.py", line 169, in backstage_push
    m.save()
  File "/Users/xiezhaorong/Desktop/my_py/djmyframework/djmyframework/apps/analysis/models/query.py", line 384, in save
    super(Query, self).save(*args, **kwargs)
  File "/Users/xiezhaorong/Desktop/my_py/djmyframework/.venv/lib/python3.7/site-packages/django/db/models/base.py", line 749, in save
    force_update=force_update, update_fields=update_fields)
  File "/Users/xiezhaorong/Desktop/my_py/djmyframework/.venv/lib/python3.7/site-packages/django/db/models/base.py", line 787, in save_base
    force_update, using, update_fields,
  File "/Users/xiezhaorong/Desktop/my_py/djmyframework/.venv/lib/python3.7/site-packages/django/db/models/base.py", line 890, in _save_table
    results = self._do_insert(cls._base_manager, using, fields, returning_fields, raw)
  File "/Users/xiezhaorong/Desktop/my_py/djmyframework/.venv/lib/python3.7/site-packages/django/db/models/base.py", line 929, in _do_insert
    using=using, raw=raw,
  File "/Users/xiezhaorong/Desktop/my_py/djmyframework/.venv/lib/python3.7/site-packages/django/db/models/manager.py", line 82, in manager_method
    return getattr(self.get_queryset(), name)(*args, **kwargs)
  File "/Users/xiezhaorong/Desktop/my_py/djmyframework/.venv/lib/python3.7/site-packages/django/db/models/query.py", line 1204, in _insert
    return query.get_compiler(using=using).execute_sql(returning_fields)
  File "/Users/xiezhaorong/Desktop/my_py/djmyframework/.venv/lib/python3.7/site-packages/django/db/models/sql/compiler.py", line 1394, in execute_sql
    cursor.execute(sql, params)
  File "/Users/xiezhaorong/Desktop/my_py/djmyframework/.venv/lib/python3.7/site-packages/django/db/backends/utils.py", line 100, in execute
    return super().execute(sql, params)
  File "/Users/xiezhaorong/Desktop/my_py/djmyframework/.venv/lib/python3.7/site-packages/django/db/backends/utils.py", line 68, in execute
    return self._execute_with_wrappers(sql, params, many=False, executor=self._execute)
  File "/Users/xiezhaorong/Desktop/my_py/djmyframework/.venv/lib/python3.7/site-packages/django/db/backends/utils.py", line 77, in _execute_with_wrappers
    return executor(sql, params, many, context)
  File "/Users/xiezhaorong/Desktop/my_py/djmyframework/.venv/lib/python3.7/site-packages/django/db/backends/utils.py", line 86, in _execute
    return self.cursor.execute(sql, params)
  File "/Users/xiezhaorong/Desktop/my_py/djmyframework/.venv/lib/python3.7/site-packages/django/db/utils.py", line 90, in __exit__
    raise dj_exc_value.with_traceback(traceback) from exc_value
  File "/Users/xiezhaorong/Desktop/my_py/djmyframework/.venv/lib/python3.7/site-packages/django/db/backends/utils.py", line 86, in _execute
    return self.cursor.execute(sql, params)
  File "/Users/xiezhaorong/Desktop/my_py/djmyframework/.venv/lib/python3.7/site-packages/django/db/backends/sqlite3/base.py", line 396, in execute
    return Database.Cursor.execute(self, query, params)
django.db.utils.IntegrityError: UNIQUE constraint failed: analysis_query.name

[2021-10-02T15:21:00+0800] [ERROR] [django.request] [pid:56644] [/Users/xiezhaorong/Desktop/my_py/djmyframework/.venv/lib/python3.7/site-packages/django/utils/log.py:228] Internal Server Error: /sync/backstage/push
