[2021-09-16T11:33:15+0800] [WARNING] [root] [pid:99871] [/Users/xiezhaorong/Desktop/my_py/djmyframework/djmyframework/framework/middleware.py:81] Traceback (most recent call last):
  File "/Users/xiezhaorong/Desktop/my_py/djmyframework/.venv/lib/python3.7/site-packages/django/core/handlers/base.py", line 113, in _get_response
    response = wrapped_callback(request, *callback_args, **callback_kwargs)
  File "/Users/xiezhaorong/Desktop/my_py/djmyframework/djmyframework/apps/sync_model/views.py", line 78, in backstage_list
    model = get_model_class(model_id)
  File "/Users/xiezhaorong/Desktop/my_py/djmyframework/djmyframework/apps/sync_model/views.py", line 41, in get_model_class
    return import_module_attr(model_id)
  File "/Users/xiezhaorong/Desktop/my_py/djmyframework/djmyframework/framework/utils/__init__.py", line 86, in import_func
    module, func = name.rsplit('.', 1)
ValueError: not enough values to unpack (expected 2, got 1)

[2021-09-16T11:33:15+0800] [ERROR] [django.request] [pid:99871] [/Users/xiezhaorong/Desktop/my_py/djmyframework/.venv/lib/python3.7/site-packages/django/utils/log.py:228] Internal Server Error: /sync/backstage/
Traceback (most recent call last):
  File "/Users/xiezhaorong/Desktop/my_py/djmyframework/.venv/lib/python3.7/site-packages/django/core/handlers/exception.py", line 34, in inner
    response = get_response(request)
  File "/Users/xiezhaorong/Desktop/my_py/djmyframework/.venv/lib/python3.7/site-packages/django/core/handlers/base.py", line 115, in _get_response
    response = self.process_exception_by_middleware(e, request)
  File "/Users/xiezhaorong/Desktop/my_py/djmyframework/.venv/lib/python3.7/site-packages/django/core/handlers/base.py", line 113, in _get_response
    response = wrapped_callback(request, *callback_args, **callback_kwargs)
  File "/Users/xiezhaorong/Desktop/my_py/djmyframework/djmyframework/apps/sync_model/views.py", line 78, in backstage_list
    model = get_model_class(model_id)
  File "/Users/xiezhaorong/Desktop/my_py/djmyframework/djmyframework/apps/sync_model/views.py", line 41, in get_model_class
    return import_module_attr(model_id)
  File "/Users/xiezhaorong/Desktop/my_py/djmyframework/djmyframework/framework/utils/__init__.py", line 86, in import_func
    module, func = name.rsplit('.', 1)
ValueError: not enough values to unpack (expected 2, got 1)
[2021-09-16T11:34:18+0800] [WARNING] [root] [pid:99871] [/Users/xiezhaorong/Desktop/my_py/djmyframework/djmyframework/framework/middleware.py:81] Traceback (most recent call last):
  File "/Users/xiezhaorong/Desktop/my_py/djmyframework/.venv/lib/python3.7/site-packages/django/core/handlers/base.py", line 113, in _get_response
    response = wrapped_callback(request, *callback_args, **callback_kwargs)
  File "/Users/xiezhaorong/Desktop/my_py/djmyframework/djmyframework/apps/sync_model/views.py", line 78, in backstage_list
    model = get_model_class(model_id)
  File "/Users/xiezhaorong/Desktop/my_py/djmyframework/djmyframework/apps/sync_model/views.py", line 41, in get_model_class
    return import_module_attr(model_id)
  File "/Users/xiezhaorong/Desktop/my_py/djmyframework/djmyframework/framework/utils/__init__.py", line 86, in import_func
    module, func = name.rsplit('.', 1)
ValueError: not enough values to unpack (expected 2, got 1)

[2021-09-16T11:34:18+0800] [ERROR] [django.request] [pid:99871] [/Users/xiezhaorong/Desktop/my_py/djmyframework/.venv/lib/python3.7/site-packages/django/utils/log.py:228] Internal Server Error: /sync/backstage/
Traceback (most recent call last):
  File "/Users/xiezhaorong/Desktop/my_py/djmyframework/.venv/lib/python3.7/site-packages/django/core/handlers/exception.py", line 34, in inner
    response = get_response(request)
  File "/Users/xiezhaorong/Desktop/my_py/djmyframework/.venv/lib/python3.7/site-packages/django/core/handlers/base.py", line 115, in _get_response
    response = self.process_exception_by_middleware(e, request)
  File "/Users/xiezhaorong/Desktop/my_py/djmyframework/.venv/lib/python3.7/site-packages/django/core/handlers/base.py", line 113, in _get_response
    response = wrapped_callback(request, *callback_args, **callback_kwargs)
  File "/Users/xiezhaorong/Desktop/my_py/djmyframework/djmyframework/apps/sync_model/views.py", line 78, in backstage_list
    model = get_model_class(model_id)
  File "/Users/xiezhaorong/Desktop/my_py/djmyframework/djmyframework/apps/sync_model/views.py", line 41, in get_model_class
    return import_module_attr(model_id)
  File "/Users/xiezhaorong/Desktop/my_py/djmyframework/djmyframework/framework/utils/__init__.py", line 86, in import_func
    module, func = name.rsplit('.', 1)
ValueError: not enough values to unpack (expected 2, got 1)
[2021-09-16T11:34:22+0800] [WARNING] [root] [pid:99871] [/Users/xiezhaorong/Desktop/my_py/djmyframework/djmyframework/framework/middleware.py:81] Traceback (most recent call last):
  File "/Users/xiezhaorong/Desktop/my_py/djmyframework/.venv/lib/python3.7/site-packages/django/core/handlers/base.py", line 113, in _get_response
    response = wrapped_callback(request, *callback_args, **callback_kwargs)
  File "/Users/xiezhaorong/Desktop/my_py/djmyframework/djmyframework/apps/sync_model/views.py", line 78, in backstage_list
    model = get_model_class(model_id)
  File "/Users/xiezhaorong/Desktop/my_py/djmyframework/djmyframework/apps/sync_model/views.py", line 41, in get_model_class
    return import_module_attr(model_id)
  File "/Users/xiezhaorong/Desktop/my_py/djmyframework/djmyframework/framework/utils/__init__.py", line 86, in import_func
    module, func = name.rsplit('.', 1)
ValueError: not enough values to unpack (expected 2, got 1)

[2021-09-16T11:34:22+0800] [ERROR] [django.request] [pid:99871] [/Users/xiezhaorong/Desktop/my_py/djmyframework/.venv/lib/python3.7/site-packages/django/utils/log.py:228] Internal Server Error: /sync/backstage/
Traceback (most recent call last):
  File "/Users/xiezhaorong/Desktop/my_py/djmyframework/.venv/lib/python3.7/site-packages/django/core/handlers/exception.py", line 34, in inner
    response = get_response(request)
  File "/Users/xiezhaorong/Desktop/my_py/djmyframework/.venv/lib/python3.7/site-packages/django/core/handlers/base.py", line 115, in _get_response
    response = self.process_exception_by_middleware(e, request)
  File "/Users/xiezhaorong/Desktop/my_py/djmyframework/.venv/lib/python3.7/site-packages/django/core/handlers/base.py", line 113, in _get_response
    response = wrapped_callback(request, *callback_args, **callback_kwargs)
  File "/Users/xiezhaorong/Desktop/my_py/djmyframework/djmyframework/apps/sync_model/views.py", line 78, in backstage_list
    model = get_model_class(model_id)
  File "/Users/xiezhaorong/Desktop/my_py/djmyframework/djmyframework/apps/sync_model/views.py", line 41, in get_model_class
    return import_module_attr(model_id)
  File "/Users/xiezhaorong/Desktop/my_py/djmyframework/djmyframework/framework/utils/__init__.py", line 86, in import_func
    module, func = name.rsplit('.', 1)
ValueError: not enough values to unpack (expected 2, got 1)
[2021-09-16T11:36:13+0800] [WARNING] [root] [pid:99871] [/Users/xiezhaorong/Desktop/my_py/djmyframework/djmyframework/framework/middleware.py:81] Traceback (most recent call last):
  File "/Users/xiezhaorong/Desktop/my_py/djmyframework/.venv/lib/python3.7/site-packages/django/core/handlers/base.py", line 113, in _get_response
    response = wrapped_callback(request, *callback_args, **callback_kwargs)
  File "/Users/xiezhaorong/Desktop/my_py/djmyframework/djmyframework/apps/sync_model/views.py", line 78, in backstage_list
    model = get_model_class(model_id)
  File "/Users/xiezhaorong/Desktop/my_py/djmyframework/djmyframework/apps/sync_model/views.py", line 41, in get_model_class
    return import_module_attr(model_id)
  File "/Users/xiezhaorong/Desktop/my_py/djmyframework/djmyframework/framework/utils/__init__.py", line 86, in import_func
    module, func = name.rsplit('.', 1)
ValueError: not enough values to unpack (expected 2, got 1)

[2021-09-16T11:36:13+0800] [ERROR] [django.request] [pid:99871] [/Users/xiezhaorong/Desktop/my_py/djmyframework/.venv/lib/python3.7/site-packages/django/utils/log.py:228] Internal Server Error: /sync/backstage/
Traceback (most recent call last):
  File "/Users/xiezhaorong/Desktop/my_py/djmyframework/.venv/lib/python3.7/site-packages/django/core/handlers/exception.py", line 34, in inner
    response = get_response(request)
  File "/Users/xiezhaorong/Desktop/my_py/djmyframework/.venv/lib/python3.7/site-packages/django/core/handlers/base.py", line 115, in _get_response
    response = self.process_exception_by_middleware(e, request)
  File "/Users/xiezhaorong/Desktop/my_py/djmyframework/.venv/lib/python3.7/site-packages/django/core/handlers/base.py", line 113, in _get_response
    response = wrapped_callback(request, *callback_args, **callback_kwargs)
  File "/Users/xiezhaorong/Desktop/my_py/djmyframework/djmyframework/apps/sync_model/views.py", line 78, in backstage_list
    model = get_model_class(model_id)
  File "/Users/xiezhaorong/Desktop/my_py/djmyframework/djmyframework/apps/sync_model/views.py", line 41, in get_model_class
    return import_module_attr(model_id)
  File "/Users/xiezhaorong/Desktop/my_py/djmyframework/djmyframework/framework/utils/__init__.py", line 86, in import_func
    module, func = name.rsplit('.', 1)
ValueError: not enough values to unpack (expected 2, got 1)
[2021-09-16T11:37:20+0800] [WARNING] [root] [pid:99974] [/Users/xiezhaorong/Desktop/my_py/djmyframework/djmyframework/framework/middleware.py:81] Traceback (most recent call last):
  File "/Users/xiezhaorong/Desktop/my_py/djmyframework/.venv/lib/python3.7/site-packages/django/core/handlers/base.py", line 113, in _get_response
    response = wrapped_callback(request, *callback_args, **callback_kwargs)
  File "/Users/xiezhaorong/Desktop/my_py/djmyframework/djmyframework/apps/sync_model/views.py", line 79, in backstage_list
    model = get_model_class(model_id)
  File "/Users/xiezhaorong/Desktop/my_py/djmyframework/djmyframework/apps/sync_model/views.py", line 41, in get_model_class
    return import_module_attr(model_id)
  File "/Users/xiezhaorong/Desktop/my_py/djmyframework/djmyframework/framework/utils/__init__.py", line 86, in import_func
    module, func = name.rsplit('.', 1)
ValueError: not enough values to unpack (expected 2, got 1)

[2021-09-16T11:37:20+0800] [ERROR] [django.request] [pid:99974] [/Users/xiezhaorong/Desktop/my_py/djmyframework/.venv/lib/python3.7/site-packages/django/utils/log.py:228] Internal Server Error: /sync/backstage/
Traceback (most recent call last):
  File "/Users/xiezhaorong/Desktop/my_py/djmyframework/.venv/lib/python3.7/site-packages/django/core/handlers/exception.py", line 34, in inner
    response = get_response(request)
  File "/Users/xiezhaorong/Desktop/my_py/djmyframework/.venv/lib/python3.7/site-packages/django/core/handlers/base.py", line 115, in _get_response
    response = self.process_exception_by_middleware(e, request)
  File "/Users/xiezhaorong/Desktop/my_py/djmyframework/.venv/lib/python3.7/site-packages/django/core/handlers/base.py", line 113, in _get_response
    response = wrapped_callback(request, *callback_args, **callback_kwargs)
  File "/Users/xiezhaorong/Desktop/my_py/djmyframework/djmyframework/apps/sync_model/views.py", line 79, in backstage_list
    model = get_model_class(model_id)
  File "/Users/xiezhaorong/Desktop/my_py/djmyframework/djmyframework/apps/sync_model/views.py", line 41, in get_model_class
    return import_module_attr(model_id)
  File "/Users/xiezhaorong/Desktop/my_py/djmyframework/djmyframework/framework/utils/__init__.py", line 86, in import_func
    module, func = name.rsplit('.', 1)
ValueError: not enough values to unpack (expected 2, got 1)
